2024-11-06 18:05:16,690 INFO    MainThread:3970312 [wandb_setup.py:_flush():79] Current SDK version is 0.18.5
2024-11-06 18:05:16,690 INFO    MainThread:3970312 [wandb_setup.py:_flush():79] Configure stats pid to 3970312
2024-11-06 18:05:16,690 INFO    MainThread:3970312 [wandb_setup.py:_flush():79] Loading settings from /home/lr2024/.config/wandb/settings
2024-11-06 18:05:16,690 INFO    MainThread:3970312 [wandb_setup.py:_flush():79] Loading settings from /home/lr2024/project/ResInf-main/wandb/settings
2024-11-06 18:05:16,690 INFO    MainThread:3970312 [wandb_setup.py:_flush():79] Loading settings from environment variables: {}
2024-11-06 18:05:16,690 INFO    MainThread:3970312 [wandb_setup.py:_flush():79] Applying setup settings: {'mode': None, '_disable_service': None}
2024-11-06 18:05:16,690 INFO    MainThread:3970312 [wandb_setup.py:_flush():79] Inferring run settings from compute environment: {'program_relpath': 'run_micro.py', 'program_abspath': '/home/lr2024/project/ResInf-main/run_micro.py', 'program': '/home/lr2024/project/ResInf-main/run_micro.py'}
2024-11-06 18:05:16,691 INFO    MainThread:3970312 [wandb_setup.py:_flush():79] Applying login settings: {}
2024-11-06 18:05:16,691 INFO    MainThread:3970312 [wandb_init.py:_log_setup():534] Logging user logs to /home/lr2024/project/ResInf-main/wandb/run-20241106_180516-s4rk9u1j/logs/debug.log
2024-11-06 18:05:16,691 INFO    MainThread:3970312 [wandb_init.py:_log_setup():535] Logging internal logs to /home/lr2024/project/ResInf-main/wandb/run-20241106_180516-s4rk9u1j/logs/debug-internal.log
2024-11-06 18:05:16,691 INFO    MainThread:3970312 [wandb_init.py:init():621] calling init triggers
2024-11-06 18:05:16,691 INFO    MainThread:3970312 [wandb_init.py:init():628] wandb.init called with sweep_config: {}
config: {}
2024-11-06 18:05:16,691 INFO    MainThread:3970312 [wandb_init.py:init():671] starting backend
2024-11-06 18:05:16,691 INFO    MainThread:3970312 [wandb_init.py:init():675] sending inform_init request
2024-11-06 18:05:16,693 INFO    MainThread:3970312 [backend.py:_multiprocessing_setup():104] multiprocessing start_methods=fork,spawn,forkserver, using: spawn
2024-11-06 18:05:16,694 INFO    MainThread:3970312 [wandb_init.py:init():688] backend started and connected
2024-11-06 18:05:16,696 INFO    MainThread:3970312 [wandb_init.py:init():783] updated telemetry
2024-11-06 18:05:16,697 INFO    MainThread:3970312 [wandb_init.py:init():816] communicating run to backend with 90.0 second timeout
2024-11-06 18:06:15,512 INFO    Thread-1 (wrapped_target):3970312 [retry.py:__call__():172] Retry attempt failed:
Traceback (most recent call last):
  File "/home/lr2024/.virtualenvs/ResInf-main/lib/python3.10/site-packages/urllib3/connection.py", line 199, in _new_conn
    sock = connection.create_connection(
  File "/home/lr2024/.virtualenvs/ResInf-main/lib/python3.10/site-packages/urllib3/util/connection.py", line 85, in create_connection
    raise err
  File "/home/lr2024/.virtualenvs/ResInf-main/lib/python3.10/site-packages/urllib3/util/connection.py", line 73, in create_connection
    sock.connect(sa)
TimeoutError: timed out

The above exception was the direct cause of the following exception:

Traceback (most recent call last):
  File "/home/lr2024/.virtualenvs/ResInf-main/lib/python3.10/site-packages/urllib3/connectionpool.py", line 789, in urlopen
    response = self._make_request(
  File "/home/lr2024/.virtualenvs/ResInf-main/lib/python3.10/site-packages/urllib3/connectionpool.py", line 490, in _make_request
    raise new_e
  File "/home/lr2024/.virtualenvs/ResInf-main/lib/python3.10/site-packages/urllib3/connectionpool.py", line 466, in _make_request
    self._validate_conn(conn)
  File "/home/lr2024/.virtualenvs/ResInf-main/lib/python3.10/site-packages/urllib3/connectionpool.py", line 1095, in _validate_conn
    conn.connect()
  File "/home/lr2024/.virtualenvs/ResInf-main/lib/python3.10/site-packages/urllib3/connection.py", line 693, in connect
    self.sock = sock = self._new_conn()
  File "/home/lr2024/.virtualenvs/ResInf-main/lib/python3.10/site-packages/urllib3/connection.py", line 208, in _new_conn
    raise ConnectTimeoutError(
urllib3.exceptions.ConnectTimeoutError: (<urllib3.connection.HTTPSConnection object at 0x7fd34cdc35b0>, 'Connection to api.wandb.ai timed out. (connect timeout=20)')

The above exception was the direct cause of the following exception:

Traceback (most recent call last):
  File "/home/lr2024/.virtualenvs/ResInf-main/lib/python3.10/site-packages/requests/adapters.py", line 667, in send
    resp = conn.urlopen(
  File "/home/lr2024/.virtualenvs/ResInf-main/lib/python3.10/site-packages/urllib3/connectionpool.py", line 843, in urlopen
    retries = retries.increment(
  File "/home/lr2024/.virtualenvs/ResInf-main/lib/python3.10/site-packages/urllib3/util/retry.py", line 519, in increment
    raise MaxRetryError(_pool, url, reason) from reason  # type: ignore[arg-type]
urllib3.exceptions.MaxRetryError: HTTPSConnectionPool(host='api.wandb.ai', port=443): Max retries exceeded with url: /graphql (Caused by ConnectTimeoutError(<urllib3.connection.HTTPSConnection object at 0x7fd34cdc35b0>, 'Connection to api.wandb.ai timed out. (connect timeout=20)'))

During handling of the above exception, another exception occurred:

Traceback (most recent call last):
  File "/home/lr2024/.virtualenvs/ResInf-main/lib/python3.10/site-packages/wandb/sdk/lib/retry.py", line 131, in __call__
    result = self._call_fn(*args, **kwargs)
  File "/home/lr2024/.virtualenvs/ResInf-main/lib/python3.10/site-packages/wandb/sdk/internal/internal_api.py", line 354, in execute
    return self.client.execute(*args, **kwargs)  # type: ignore
  File "/home/lr2024/.virtualenvs/ResInf-main/lib/python3.10/site-packages/wandb/vendor/gql-0.2.0/wandb_gql/client.py", line 52, in execute
    result = self._get_result(document, *args, **kwargs)
  File "/home/lr2024/.virtualenvs/ResInf-main/lib/python3.10/site-packages/wandb/vendor/gql-0.2.0/wandb_gql/client.py", line 60, in _get_result
    return self.transport.execute(document, *args, **kwargs)
  File "/home/lr2024/.virtualenvs/ResInf-main/lib/python3.10/site-packages/wandb/sdk/lib/gql_request.py", line 58, in execute
    request = self.session.post(self.url, **post_args)
  File "/home/lr2024/.virtualenvs/ResInf-main/lib/python3.10/site-packages/requests/sessions.py", line 637, in post
    return self.request("POST", url, data=data, json=json, **kwargs)
  File "/home/lr2024/.virtualenvs/ResInf-main/lib/python3.10/site-packages/requests/sessions.py", line 589, in request
    resp = self.send(prep, **send_kwargs)
  File "/home/lr2024/.virtualenvs/ResInf-main/lib/python3.10/site-packages/requests/sessions.py", line 703, in send
    r = adapter.send(request, **kwargs)
  File "/home/lr2024/.virtualenvs/ResInf-main/lib/python3.10/site-packages/requests/adapters.py", line 688, in send
    raise ConnectTimeout(e, request=request)
requests.exceptions.ConnectTimeout: HTTPSConnectionPool(host='api.wandb.ai', port=443): Max retries exceeded with url: /graphql (Caused by ConnectTimeoutError(<urllib3.connection.HTTPSConnection object at 0x7fd34cdc35b0>, 'Connection to api.wandb.ai timed out. (connect timeout=20)'))
2024-11-06 18:06:16,307 WARNING MainThread:3970312 [wandb_init.py:init():1260] interrupted
Traceback (most recent call last):
  File "/home/lr2024/.virtualenvs/ResInf-main/lib/python3.10/site-packages/wandb/sdk/wandb_init.py", line 1256, in init
    return wi.init()
  File "/home/lr2024/.virtualenvs/ResInf-main/lib/python3.10/site-packages/wandb/sdk/wandb_init.py", line 819, in init
    result = run_init_handle.wait(
  File "/home/lr2024/.virtualenvs/ResInf-main/lib/python3.10/site-packages/wandb/sdk/lib/mailbox.py", line 283, in wait
    found, abandoned = self._slot._get_and_clear(timeout=wait_timeout)
  File "/home/lr2024/.virtualenvs/ResInf-main/lib/python3.10/site-packages/wandb/sdk/lib/mailbox.py", line 130, in _get_and_clear
    if self._wait(timeout=timeout):
  File "/home/lr2024/.virtualenvs/ResInf-main/lib/python3.10/site-packages/wandb/sdk/lib/mailbox.py", line 126, in _wait
    return self._event.wait(timeout=timeout)
  File "/home/lr2024/anaconda3/envs/pytorch/lib/python3.10/threading.py", line 607, in wait
    signaled = self._cond.wait(timeout)
  File "/home/lr2024/anaconda3/envs/pytorch/lib/python3.10/threading.py", line 324, in wait
    gotit = waiter.acquire(True, timeout)
KeyboardInterrupt
2024-11-06 18:06:16,311 WARNING MsgRouterThr:3970312 [router.py:message_loop():77] message_loop has been closed
